Workbook
Name _Hlk99048333: '17025 SAL'!$B$179

Sheet INICIO
A1: Directorio OEC | J1: Código No. : | K1: Páginas:
J2: ECA-MP-P09-F03 | K2: Página: 1 de 10
J3: Fecha de entrada en vigencia | K3: Versión:
J4: 45503 | K4: 4

Sheet 17025 SAL
B1: Norma de Referencia: INTE ISO/IEC 17025:2017 Requisitos generales para la competencia de laboratorios de ensayo y calibración | AN1: =4*365 -> 1460
A2: Nombre del OEC | B2: Nombre Razón social | C2: Tipo OEC | D2: Estatus | E2: Sector | F2: # Expediente | G2: # Acreditación | H2: Fecha firma de contrato | I2: Renovación de contrato | J2: Fecha de Otorgamiento | K2: Resumen fecha ampliaciones | L2: Nombre Representante ECA | M2: Email para notificaciones (oficial) | N2: Email alternativos (copias de comunicación) | O2: Teléfono | P2: Fax | Q2: País | R2: Dirección | S2: Provincia | T2: Cédula Jurídica | U2: Sitio Web | V2: Representante Legal | W2: # Identificación | X2: Estado Civil | Y2: Nacionalidad | Z2: Profesión | AA2: Dirección para recibir notificaciones | AB2: Correo electrónico | AC2: Cargo dentro del OEC: | AD2: Contacto Dpto. de Facturación/ Cobro | AE2: Nombre | AF2: Teléfono2 | AG2: Dirección3 | AH2: Fax4 | AI2: Email | AJ2: Horario | AK2: Empresa | AL2: Observaciones
A3: AGQ Costa Rica S.A. | B3: AGQ Costa Rica S.A. | C3: LE | D3: A | E3: Privado | F3: LE-002 | G3: LE-002 | H3: 45128 | I3: ='17025 SAL'!$H3+$AN$1 -> 46588 | J3: 35536 | L3: Jeisson Cárdenas | M3: jeisson.cardenas@agqlabs.com | N3: noelia.lopez@agqlabs.com, andres.villalobos@agqlabs.com, David.solorzano@agqlabs.com | O3: 2286-1168 | P3: 2286-1168 | Q3: Costa Rica | R3: San José, de la Iglesia 100 m oeste, 75 m norte y 75 m oeste, Barrio Los Álamos, San Francisco de Dos Ríos | S3: San José | T3: 3-101-74595 | U3: https://agqlabs.cr/ | V3: Andrés Villalobos Herrera | W3: 1-0984-0656 | X3: Casado | Y3: Costarricense | Z3: Ingeniero agronomo | AA3: San José, San Francisco de Dos Ríos, de la escuela República Dominicana 50 m norte y 75 m oeste | AB3: andres.villalobos@agqlabs.com | AC3: Gerente General | AD3: Romario Masis Valle | AE3: AGQ Costa Rica S.A. | AF3: 2286-1168 | AG3: San José, de la Iglesia 100 oeste, 75 norte y 75 oeste, Barrio Los Álamos, San Francisco de Dos Ríos | AH3: 2286-1168 | AI3: facturae-cr@agqlabs.com | AJ3: 8 am A 6 pm | AK3: AGQ Costa Rica S.A. | AL3: Cambio en razón social, ahora es AGQ Costa Rica
A4: Laboratorio Químico AQYLA S.A. | B4: Asesorías Químicas AQYLA Sociedad Anónima | C4: LE | D4: A | E4: Privado | F4: LE-003 | G4: LE-003 | H4: 45859 | I4: No aplica | J4: 35879 | L4: Elizabeth Mojica Araya | M4: aqylasa@ice.co.cr | N4: emojica.aqylasa@hotmail.com | O4: 22723159 | P4: 22723159 | Q4: Costa Rica | R4: San José, 25 m Sur de Esquina Sur Oeste del Parque, Curridabat. | S4: San José | T4: 3-101-093975-35 | U4: =HYPERLINK("http://www.labaqylasa.com/","www.labaqylasa.com ") -> www.labaqylasa.com | V4: Lic Leonor Rodriguez Montero | W4: 1-418-303 | X4: Soltera | Y4: Costarricense | Z4: Lic Quimica | AA4: San José, 25 Sur de Esquina Sur Oeste del Parque, Curridabat. | AC4: Directora Técnica | AD4: Lic Elizabeth Mojica | AE4: Asesorias Quimicas Aqylasa | AF4: 22723159 | AG4: San José, 25 Sur de Esquina Sur Oeste del Parque, Curridabat. | AH4: 22723159 | AI4: =HYPERLINK("mailto:aqylasa@ice.co.cr","aqylasa@ice.co.cr ") -> aqylasa@ice.co.cr | AJ4: 8Am a 5 pm | AK4: AQYLA S.A | AL4: Suspensión parcial voluntario del 08/03/2024 al 08/03/2025
A5: Laboratorio del Centro de Investigación y de Servicios Químicos y Microbiológicos- CEQIATEC | B5: Instituto Tecnológico de Costa Rica | C5: LE | D5: A | E5: Académico | F5: LE-004 | G5: LE-004 | H5: 45414 | I5: ='17025 SAL'!$H5+$AN$1 -> 46874 | J5: 36707 | L5: Federico Masís Meléndez / Adrián Flores | M5: fmasis@itcr.ac.cr | N5: aflores@tec.ac.cr; aflores@itcr.ac.cr | O5: 2550-2368 | P5: 2591-5147 | Q5: Costa Rica | R5: Cartago, 400 este, Estadio Fello Meza, Edificio Núcleo integrado de escuela de Química e Ingeniería Ambiental" (Sede Central I.T.C.R.) | S5: Cartago | T5: 4000-042145-07 | U5: =HYPERLINK("http://www.tec.ac.cr/","www.tec.ac.cr") -> www.tec.ac.cr | V5: María Estrada Sánchez | AA5: Cartago, 400 este, Estadio Fello Meza, (Sede Central I.T.C.R.) | AC5: Rector | AD5: Noemy Quirós Bustos | AE5: Fundatec | AF5: 2550-2368 | AG5: Cartago, 400 este, Estadio Fello Meza, Edificio Núcleo integrado de escuela de Química e Ingeniería Ambiental" (Sede Central I.T.C.R.) | AH5: 25915147 | AI5: =HYPERLINK("mailto:ceqiatec@itcr.ac.cr","ceqiatec@itcr.ac.cr") -> ceqiatec@itcr.ac.cr | AJ5: 7:30 a.m. a 12:00 md y de 1:00 a 4:30 p.m. | AK5: ITCR | AL5: 18.02.2019 Reducción voluntaria para los ensayos PT-QU-3, cloruros, PT-QU-5, fluoruros y PT-QU-6, nitratos. / 07.06.2017 reducción del ensayo recuento heterotrofo en placa para agua /23.01.2017 reducción de alcance para el ensayo físico químico en agua residual: demanda química de oxígeno / 12.04.2016 reducción de alcance para los metodos PT-QUI-02-08 para determinación de sulfato en agua, PT-QUI-02-09 para determinación de cromo en agua, Método desarrollado en laboratorio (PT-QUI-03). Cromatografía de gases. Extracción en fase sólida para determinación de residuos de plaguicidas organofosforados en Leche, Método no normalizado, modificado (Application, Note 64, Sigma-Aldrich Co. 1997) (PT-QUI-03) Cromatografía de gases Extracción en fase sólida para determinación de Residuo de plaguicidas organofosforados y organoclorados en agua potable y residual, Método desarrollado en laboratorio (PT-QUI-03). Cromatografía de gases. Extracción en fase sólida para la determinación de Residuo de plaguicidas organofosforados en Frutas y vegetales (banano, piña, mango, camote, chile dulce, chayote) / 01.07.2014 para pruebas de esterilidad para controles biológicos en dispositivos de control de procesos de esterilización
A6: Laboratorio de Ensayos Conducen | B6: CONDUCEN SOCIEDAD DE RESPONSABILIDAD LIMITADA | C6: LE | D6: A | E6: Privado | F6: LE-006 | G6: LE-006 | H6: 43909 | I6: ='17025 SAL'!$H6+$AN$1 -> 45369 | J6: 37882 | L6: Juan Arias Araya | M6: juan.arias@prysmiangroup.com | N6: nikol.castillo@prysmiangroup.com edwin.hernandez@prysmiangroup.com | O6: 22984800 | P6: No aplica | Q6: Costa Rica | R6: Carretera Interamericana Norte, frente a Real Cariari. PROVINCIA 04 HEREDIA, CANTON 07 BELEN, SAN ANTONIO, KILOMETRO 11.5 AUTOPISTA GENERAL CAÑAS, INTERSECCION SAN ANTONIO. | S6: Heredia | T6: 3102011928 | U6: https://central-america.prysmian.com/es | V6: Adriana de lo Ángeles Delgado Castillo | W6: 1-1268-0188 | X6: Casado | Y6: Costarricense | Z6: Administradora de Empresas | AA6: Carretera Interamericana Norte, frente a Real Cariari. PROVINCIA 04 HEREDIA, CANTON 07 BELEN, SAN ANTONIO, KILOMETRO 11.5 AUTOPISTA GENERAL CAÑAS, INTERSECCION SAN ANTONIO. | AB6: adriana.delgado@prysmian.com | AC6: Directora Financiera | AD6: Depto. Crédito y Cobro. | AE6: Depto. Crédito y Cobro. | AF6: No aplica | AG6: Carretera Interamericana Norte, frente a Real Cariari. PROVINCIA 04 HEREDIA, CANTON 07 BELEN, SAN ANTONIO, KILOMETRO 11.5 AUTOPISTA GENERAL CAÑAS, INTERSECCION SAN ANTONIO. | AI6: luisfernando.roman@prysmian.com | AJ6: 8 am a 5:30 pm | AK6: CONDUCEN | AL6: 4/8/25: Se actualizan datos de contacto para facturación y datos del representante legal 15.07.2016 reducción de alcance para el ensayo visual en alambres, cables cordones desnudos con aislamiento area transversal 0,205mm2 para la determinación del marcado del producto / 27.05.2016 DETERMINACIÓN DE LA CANTIDAD DE HUMOS y DETERMINACIÓN DE LA CANTIDAD DE GAS ÁCIDO HALOGENADO en Alambres, Cable, Cordones desnudos o con aislamiento y/o cubiertas con Área de sección transversal de 0,205 mm² a 507,0 mm² (Alcance Original) / Antes de enviar una factura deben enviar una cotizacion del servicio brindado.
A7: Laboratorio del Centro de Investigación en Contaminación Ambiental-CICA | B7: Universidad de Costa Rica | C7: LE | D7: A | E7: Académico | F7: LE-007 | G7: LE-007-R01 | H7: 45147 | I7: ='17025 SAL'!$H7+$AN$1 -> 46607 | J7: 36707 | L7: Johan Molina Delgado | M7: calidad.cica@ucr.ac.cr | O7: 2511-8208 | P7: N/A | Q7: Costa Rica | R7: San José, Cuidad Universitaria Rodrigo Facio, atrás de la biblioteca de salud, San Pedro de Montes de Oca. | S7: San José | T7: 3-006101757 | U7: https://cica.ucr.ac.cr/ | V7: Carlos Araya Leandro | W7: 3-0305-0948 | X7: Casado | Y7: Costarricense | Z7: Doctor en Economía, Gestión y Control de Entidades y Políticas Públicas. | AA7: San José, Sede Univesitaria Rodrigo Facio, Edificio Administrativo B, Segundo Piso, Oficina de Rectoría, San Pedro de Montes de Oca. | AC7: Rector Universidad de Costa Rica | AD7: María Soledad Vanegas Avilés | AE7: FUNDEVI | AF7: 25118205 | AG7: San José, Cuidad Universitaria Rodrigo Facio, atrás de la biblioteca de salud, San Pedro de Montes de Oca. | AH7: 2253-1363 | AI7: =HYPERLINK("mailto:maria.vanegas.aviles@gmail.com","maria.vanegas.aviles@gmail.com ") -> maria.vanegas.aviles@gmail.com | AJ7: 8:00-12:00 y 13:00-17:00 | AK7: UCR | AL7: 12.04.2016 Reducción de alcance para el metodo de referencia MAR-14 para la determinación del ensayo Mancozeb en rroz, apio, banano, brócoli, cebolla, chile, coliflor, culantro, chayote, camote, espinaca, frijoles, fresa, granadilla, lechuga, limón, melón, mora, minivegetales, mango, manzana, naranja, ñame, pepino, pera, papa, piña, papaya, repollo, sandía, tomate, tiquisque, vainica, yuca y zanahoria / Reducción de alcance 12.05.2015 analitos del ensayo “MAR-05: Determinación de residuos de plaguicidas en alimentos por cromatografía de gases”de los analitos: Diazinón, Forato, Terbufós, Acefato, Clorotalonil y Foxim. Reducción de alcance 28.04.2015 para el ensayo: “MAQA-19: Determinación de metales por absorción atómica utilizando horno de grafito (GFAAS) para los elementos antimonio, selenio y estaño” 24.02.2015 Reducción de alcance para los ensayos MAR 5: Determinación de residuos de plaguicidas por cromatografía de gases: Causafos, Fenamifos, Metamidofos, Triadimefon, Triazofós, Deltametrina. 16.12.2014 Reducción de alcance para los ensayos MACA-17 Determinación de la concentración de gases O2, CO2, CO, SO2, NO, NO2 y NOx, en los gases de escape de una fuente fija EPA CTM-034. MACA-07 Partículas suspendidas en aire PM-10. Determinación de la concentración de partículas respirables (PM-10). 10.06.2014. Suspensión voluntaria parcial del alcance del 10.06.2014 al 10.12.2014 para los ensayos: determinación de gases O2, CO2, CO, SO2, NO, NO2 y NOx, en los gases de escape de una fuente fija EPA CTM-034. 27.05.2014 1. MAR-1 Determinación de residuos de plaguicidas en muestra de agua por cromatografía de gases utilizando extracción líquido analito: Acefato, Captán, Clorotalonil, Forcim, Metalaxil, Metamidofos, Monocrotofós. 2. MAR-7 Determinación de plaguicidas ácidos y neutros en agua por extracción en fase sólida y cromatografía líquida de alta resolución analito: Dicamba, Disulfotón, Fentión. 3. MAR- 9 Determinación de residuos carbonatados en aguas utilizando extracción líquido y CLAR analito: 3- cetocarbofuran. 4. MAR-24 Determinación de residuos de fenamidona por cromatografía de gases en muestras de piña: corazón, pulpa, cáscara y fruto completo 12.11.2013 Reducción de alcance en los ensayos determinación de Caudal en aguas, aguas residuales y aguas de mar, Determinación de Sólidos Volátiles y fijos en aguas, aguas residuales y aguas de mar 14.01.2014 Suspensión voluntaria parcial del alcance del 14.01.2014 al 14.07.2014 para los ensayos: MAR-5:Determinaciòn de residuos de Plaguicidas, por cromatografía de gases en matrices de origen vegetal: con elevado contenido de agua y contenido escaso o ausencia de clorofila, elevado contenido de ácido, elevado contenido de agua y clorofila, elevado contenido de aceite o grasa, y materiales secos. MAQA-19: Metales pesados MAQA-39: Mercurio.
A8: Laboratorios de Control de Calidad RECOPE | B8: Refinadora Costarricense de Petroleo Sociedad Anónima | C8: LE | D8: A | E8: Público | F8: LE-009/LE-010 | G8: LE-009/LE-010 | H8: 43900 | I8: ='17025 SAL'!$H8+$AN$1 -> 45360 | J8: 36944 | K8: A10: 09/07/2025 | L8: Erick Solano , Francisco Padilla | M8: gestión.calidad@recope.go.cr gestioncalidad.comunicacioneseca@recope.go.cr | N8: francisco.padilla@recope.go.cr erick.solano@recope.go.cr | O8: (506) 2550-3667 Móvil: (506) 8819-9383 2550-3553 / 2550-3750 / 8310-0137 Erick Solano, 2550-3667 3500 367 Francisco Padilla: 2436-6049 | P8: No aplica | Q8: Costa Rica | R8: Cartago, Plantel de Distibución El Alto Recope, Ochomogo de Cartago | S8: Cartago | T8: 3-101-007749 | U8: =HYPERLINK("http://www.recope.go.cr/","www.recope.go.cr ") -> www.recope.go.cr | V8: Luis Manuel Sánchez Esquierdo | W8: 700860334 | X8: Casado | Y8: Costarricense | Z8: Ingeniero Químico | AA8: Terminal el Alto de Ochomogo, kilómetro 12 km, Ruta 2, Ochomogo, San Nicolás, Cartago. | AC8: Gerente de Operaciones | AD8: Tesorería | AE8: Hubert López Chacón | AF8: 2284-4740 | AG8: Calle 108, Ruta 32. Km 0, Edificio Hernán Garrón Salazar San Francisco de Goicoechea San José, Costa Rica | AH8: No aplica | AI8: factura@recope.go.cr | AJ8: 7:00 am a 3:00 pm | AK8: RECOPE | AL8: El cliente de la factura debe ser: Laboratorio Control de Calidad RECOPE, LE-009
A9: Laboratorio San Martín | C9: LE | D9: A | E9: Privado | F9: LE-012 | G9: LE-012 | H9: 43963 | I9: ='17025 SAL'!$H9+$AN$1 -> 45423 | J9: 37194 | L9: Dr. Juan Carlos Rojas Carrión | M9: jcrojas@labsanmartin.com | N9: carolina@labsanmartin.com | O9: 2222-3635 | P9: 2222-2486 | Q9: Costa Rica | R9: San José, Calles 1 y 3, Ave. 10, del Banco Popular 300 m sur y 25 m este. | S9: San José | T9: 3-101-74483 | U9: =HYPERLINK("http://www.labsanmatin.com/","www.labsanmatin.com ") -> www.labsanmatin.com | V9: Dr. Juan Carlos Rojas Carrión | W9: 1-0576-0622 | X9: Casado | Y9: Costarricense | Z9: Microbiólogo | AA9: San José, Calles 1 y 3, Ave. 10, del Banco Popular 300 sur y 25 este. | AC9: Gerente General | AD9: Carolina Rojas Sánchez | AE9: Centro Médico San Martín | AF9: 2222-3635 | AG9: San José, Calles 1 y 3, Ave. 10, del Banco Popular 300 sur y 25 este. | AH9: 2222-2486 | AI9: =HYPERLINK("mailto:carolina@labsanmartin.com","carolina@labsanmartin.com ") -> carolina@labsanmartin.com | AJ9: L-V 7am - 5 pm S 8am - 12 md | AK9: San Martin | AL9: Fecha de actualización de listado de alcance flexible: 22.01.2014
A10: Laboratorio Echandi | B10: Microbiologos Asociados Sociedad Anonima | C10: LE | D10: A | E10: Privado | F10: LE-014 | G10: LE-014 | H10: 45190 | I10: ='17025 SAL'!$H10+$AN$1 -> 46650 | J10: 37571 | L10: Federico Echandi | M10: fechandi@labechandi.com | N10: nvargas@labechandi.com aviquez@labechandi.com | O10: 7106-2648 /2258-4334/8666-0423 | Q10: Costa Rica | R10: San José, 25 metros norte de el restaurante Mac Donalds, contiguo a Auto Pitz, San Rafael de Escazú | S10: San José | T10: 3-101-014359-26 | U10: www.labechandi.com | V10: Federico Echandi | W10: 1-1111-0536 | Y10: Costarricense | AA10: San José, 25 metros norte de el restaurante Mac Donalds, contiguo a Auto Pitz, San Rafael de Escazú | AB10: fechandi@labechandi.com | AC10: Gerente General | AD10: Federico Echandi | AE10: Microbiólogos Asociados S.A. | AF10: 7106-2648 /2258-4334 | AG10: San José, 25 metros norte de el restaurante Mac Donalds, contiguo a Auto Pitz, San Rafael de Escazú | AH10: 2221-7159 | AI10: =HYPERLINK("mailto:labechandi@ice.co.cr","labechandi@ice.co.cr") -> labechandi@ice.co.cr | AJ10: L a V de 8 am a 5 pm | AK10: Echandi - Sta Rita | AL10: 2022.01.18 Reducción voluntaria del alcance de acreditación de los siguientes ensayos: LE-AA-I09, LE-AA-I10 y LE-DE-100// 22.10.2013 Reducción de alcances en los inmunoensayos: Canabinoides (THC) en orina. Metabolito de Cocaína en orina. // 17.09.2018 en el área de química clínica para los ensayos de Hierro y Capacidad de Fijación de Hierro. //
A11: Laboratorio Nacional de Materiales y Modelos Estructurales LANAMME-UCR. | B11: Universidad de Costa Rica | C11: LE | D11: R | E11: Académico | F11: LE-018 | L11: Ing. Humberto Tioli Mora | M11: emmanuel.badilla@ucr.ac.crjose.tioli@ucr.ac.cr | N11: direccion.lanamme@ucr.ac.crmaria.castrosoto@ucr.ac.cr | O11: 2511-2500/ 2511-2531 | P11: 2511-4440 | Q11: Costa Rica | R11: San José, 500 m Norte de Supermercado Muñoz & Nanne, Ciudad de la Investigación, Universidad de Costa Rica, San Pedro de Montes de Oca. | S11: San José | T11: 4-000-042149 | U11: http://www.lanamme.ucr.ac.cr/ | V11: Carlos Araya Leandro | W11: 3-0305-0948 | X11: Casado | Y11: Costarricense | Z11: Doctor en Economía, Gestión y Control de Entidades y Políticas Públicas. | AD11: Ing. Humberto Tioli | AE11: Universidad de Costa Rica | AF11: 2511-2514 | AG11: San José, 500 Norte de Supermercado Muñoz & Nanne, Ciudad de la Investigación, Universidad de Costa Rica, San Pedro de Montes de Oca. | AH11: 2511-4440 | AI11: jose.tioli@ucr.ac.cr; maria.castrosoto@ucr.ac.cr; randall.valle@ucr.ac.cr; facturacionelectronica.lanamme@ucr.ac.cr; emmanuel.badilla@ucr.ac.cr | AJ11: 08:00 - 17:00 | AK11: UCR | AL11: Facturar a nombre de: Universidad de Costa Rica
A12: Laboratorio de Calibración SCM Metrología y Laboratorios S.A. | B12: SCM Metrología y Laboratorios Sociedad Anónima | C12: LC | D12: A | E12: Privado | F12: LC-020 | G12: LC-020 | H12: 45869 | I12: No aplica | J12: 37718 | L12: Carlos Alvarado / Jose Marvin Rodríguez Vásquez | M12: carlos.alvarado@scmmetrologia.com | N12: jose.rodriguez@scmmetrologia.com | O12: (+506) 4020-1201 / (+506) 7206-1540 / (+506) 7206-1566 | P12: 4020-1203 | Q12: Costa Rica | R12: Zona Franca Bes, L1, Coyol, Alajuela | T12: =HYPERLINK("http://www.scmmetrologia.com/Newsite/","3-101-271623 ") -> 3-101-271623 | U12: =HYPERLINK("http://www.scmmetrologia.com/Newsite/","http://www.scmmetrologia.com/Newsite/") -> http://www.scmmetrologia.com/Newsite/ | V12: Edgar Sánchez Molina | W12: 2-0459-0214 | X12: Casado | Y12: Costarricense | Z12: Químico | AA12: vecino de San Pablo de Heredia, Residencial Doña Nina, casa 19. | AC12: Director | AD12: Laura Molina Salazar | AE12: SCM Metrología y Laboratorio S.A. | AF12: 2431-5252 ext. 102 | AG12: Alajuela, 2 km Este del Aeropuerto Internacional Juan Santamaría, Río Segundo de Alajuela | AH12: 2432-4180 | AI12: =HYPERLINK("mailto:laura.molina@scmmetrologia.com","laura.molina@scmmetrologia.com") -> laura.molina@scmmetrologia.com | AJ12: 7:00 am a 4:30 pm | AK12: SCM | AL12: 11.06.2019. Mantenimiento de acreditación otorgada en CA-008-2019
A13: Laboratorio Pruebas de Paternidad | B13: Caja Costarricense de Seguro Social | C13: LE | D13: A | E13: Público | F13: LE-021 | G13: LE-021 | H13: 45552 | I13: No aplica | J13: 37718 | L13: Lucía Obando Madrigal | M13: lobandom@ccss.sa.cr | N13: jpmontes@ccss.sa.cr | O13: 2257-5342 | P13: 22575342 | Q13: Costa Rica | R13: San José, Avenida central, calles 16 y 20, edificio Joissar, 3° piso. | S13: San José | T13: 4-000-042147 | U13: http://portal.ccss.sa.cr/portal/page/portal/Gerencia_Medica/Laboratorio_de_Pruebas_de_Paternidad | V13: RANDAL ALAN ÁLVAREZ JUÁREZ | W13: 5-0290-0193 | Y13: costarricense | Z13: Medico | AA13: San José, Avenida central, calles 16 y 20, edificio Joissar, 3° piso. | AC13: Gerente Médico CCSS | AD13: Diana Jane Conejo Rodríguez; José Joaquín Solano Solís | AE13: CCSS, Laboratorio de Pruebas de Paternidad | AF13: 2257-5342 | AG13: San José, Avenida central, calles 16 y 20, edificio Joissar, 3° piso. | AH13: 2257-5342 | AI13: =HYPERLINK("mailto:jjsolano@ccss.sa.crjpzunigg@ccss.sa.cr","dconejohm@ccss.sa.cr; jjsolano@ccss.sa.cr") -> dconejohm@ccss.sa.cr; jjsolano@ccss.sa.cr | AJ13: Lunes a jueves de 7:00 a 16:00; viernes 7:00 a 15:00 | AK13: CCSS - Pruebas de Paternidad
A14: La casa de la Balanza de Cartago S.A. | B14: La casa de la Balanza de Cartago Sociedad Anónima | C14: LC | D14: A | E14: Privado | F14: LC-025 | G14: LC-025 | H14: 43843 | I14: ='17025 SAL'!$H14+$AN$1 -> 45303 | J14: 38334 | L14: Roberto Granados Solis | M14: calidad@casabalanza.com | N14: servicioalcliente@casabalanza.com | O14: 2552-6311 | P14: 2551-4751 | Q14: Costa Rica | R14: Cartago, del Banco de Costa Rica, 200 m Sur, 50 m este y 25 m al Sur, San Rafael de Oreamuno. | S14: Cartago | T14: 3-101-136275 | U14: =HYPERLINK("http://www.casabalanza.com/","www.casabalanza.com") -> www.casabalanza.com | V14: Roberto Granados Solís | W14: 3-280-863 | X14: Casado | Y14: Costarricense | Z14: Mecánico Industrial | AA14: Cartago, del Banco de Costa Rica, 200 Sur y 50 este, San Rafael de Oreamuno. | AC14: Presidente | AD14: Gabriela Vargas Araya | AE14: La Casa de la Balanza de Cartago, S.A. | AF14: 2552-7293 | AG14: Cartago, del Banco de Costa Rica, 200 Sur y 50 este, San Rafael de Oreamuno. | AH14: 2551-4751 | AI14: =HYPERLINK("mailto:gvargas@casabalanza.com","gvargas@casabalanza.com") -> gvargas@casabalanza.com | AJ14: Lunes a Viernes de 10 a.m a 12.a.m y 2:00 pm a 4:00 p.m. | AK14: La casa de la Balanza de Cartago S.A. | AL14: Los pagos se hacen por transferencia los días viernes.
A15: Vieto & Asociados S.A. | B15: Vieto & Asociados Sociedad Anónima | C15: LE | D15: A | E15: Privado | F15: LE-026 | G15: LE-023 | H15: 45378 | I15: ='17025 SAL'!$H15+$AN$1 -> 46838 | J15: 38590 | K15: A07: 15/10/2024 | L15: Susy Vieto de la Fuente | M15: susy.vieto@vieto.com | N15: calidad@vieto.com | O15: 2268-8297 ext: 225 | P15: 2268-9457 | Q15: Costa Rica | R15: Heredia, del rancho de Doña Lela 3.5km sobre la autopista Braulio Carrillo, después del segundo puente peatonal 400 norte primer entrada de lastre a mano derecha, San Luis de Santo Domingo. | S15: Heredia | T15: 3-101-029579-15 | U15: =HYPERLINK("http://www.vieto.com/","www.vieto.com") -> www.vieto.com | V15: Susy Vieto de la Fuente | W15: 1-0753-0214 | X15: Casada | Y15: Costarricense | Z15: Administradora de empresas | AA15: =HYPERLINK("mailto:susy.vieto@vieto.com","susy.vieto@vieto.com calidad@vieto.com") -> susy.vieto@vieto.com calidad@vieto.com | AC15: Gerente de Calidad | AD15: Vanessa Loaiza | AE15: Vieto & Asociados S.A. | AF15: 2268-8297 | AG15: Heredia, del rancho de Doña Lela 3.5km sobre la autopista Braulio Carrillo, después del segundo puente peatonal 400 norte primer entrada de lastre a mano derecha, San Luis de Santo Domingo. | AH15: 2268-9457 | AI15: =HYPERLINK("mailto:contabilidad@vieto.com","contabilidad@vieto.com") -> contabilidad@vieto.com | AJ15: Lunes a viernes de 7:00am a 5:00pm Sábados 7:00am a 12:00md | AK15: Vieto y Asociados | AL15: De lunes a viernes cerrado de 12:00md a 1:00pm
A16: Agrotec Laboratorios Analíticos S.A. | B16: Agrotec Laboratorios Analíticos Sociedad Anónima | C16: LE | D16: A-S | E16: Privado | F16: LE-027 | G16: LE-029 | H16: 45411 | I16: ='17025 SAL'!$H16+$AN$1 -> 46871 | J16: 38635 | K16: A01: 12/07/2024 | L16: Frank Rivas, Priscilla Meléndez Vargas | M16: frank.rivas@agrotec.net | N16: priscila.melendez@agrotec.net eric.arauz@agrotec.net ana.angulo@agrotec.net | O16: 4040-0390 | Q16: Costa Rica | R16: Alajuela, Alajuela, San Rafael. Ofibodegas del Oeste, local 13. | S16: San José | T16: 3-101-161663 | U16: NA | V16: Steven Mullins Cordero | W16: 900930880 | X16: Divorciado | Y16: Costarricense | Z16: Administrador de Empresas | AA16: San José, Calles 36 y 38, Avenida 4, Paseo Colón, Mata Redonda. O al correo eric.arauz@agrotec.net; | AC16: Gerente General | AD16: Ana Cecilia Angulo Segura | AE16: Agrotec Laboratorios Analíticos S.A. | AF16: 4081-1010 | AG16: San José, Calles 36 y 38, Avenida 4, Paseo Colón, Mata Redonda. | AH16: 4081-1010 | AI16: =HYPERLINK("mailto:ana.angulo@agrotec.net","ana.angulo@agrotec.net") -> ana.angulo@agrotec.net | AJ16: Lunes a Viernes de 7:15 am-12:00 md | AK16: Agrotec | AL16: 20-12-22: Por favor cambiar al representante de Agrotec ante ECA, eliminar a Alejandra Montenegro, en su lugar queda Priscila Meléndez Vargas, este es su correo priscila.melendez@agrotec.net
A17: Laboratorio Clínico Médico Dr. Carlos Páez Sotela | C17: LE | D17: R | E17: Privado | F17: LE-028 | G17: LE-022 | I17: ='17025 SAL'!$H17+$AN$1 -> 1460 | J17: 38516 | L17: Dr. Marco Molina | M17: mamolina10@hotmail.com | O17: 2255-0561 | P17: 2258-5026 | Q17: Costa Rica | R17: San José, detrás de Pollo Campero en la Sabana. | S17: San José | T17: Servicios Clinicos la Sabana 3-101-570114 | U17: =HYPERLINK("http://www.laboratoriospaez.com/","www.laboratoriospaez.com") -> www.laboratoriospaez.com | V17: Carlos R Paez Sotela | W17: 9-011-206 | X17: casado | Y17: Costarricense | Z17: Microbiólogo | AA17: San José, detrás de Pollo Campero en la Sabana. | AC17: Alta Dirección | AD17: Sr. Jorge Sánchez | AE17: Servicios Clínicos La Sabana razón social | AF17: 2233-8318 | AG17: San José, detrás de Pollo Campero en la Sabana. | AH17: 2258-5026 | AI17: =HYPERLINK("mailto:Jsan@laboratoriospaez.com;","Jsan@laboratoriospaez.com;") -> Jsan@laboratoriospaez.com; | AJ17: 8 am a 5 pm | AK17: Laboratorio Clínico Médico Dr. Carlos R Páez Sotela | AL17: 15.05.2018 retiro voluntario de acreditación / 07.06.2017 reducción del alcance dejando solo los ensayos de Suero, Orina y Líquido cefalorraquídeo: Glucosa AU 480 BECKMAN COULTER OSR 6521, Suero: Colesterol Total AU 480 BECKMAN COULTER OSR 6116, Suero: hTSH II ultrasensible Hormona tiroestimulant humana 7K 62-25 Arquitect de Abbott, y Suero: Antígeno Prostático Específico PSA Total 7K 70-25 Arquitect de Abbott/24.05.2016 Reducción de alcance para los ensayos de: Prolactina humana en suero, Fenitoína 7ª en suero, Carbamazepina en suero / 08.09.2015 Reducción parcial del alcance para los siguientes ensayos: Canabinoides 3B28-20 Arquitect de Abbott y Cocaína metabolitos 3B24-20 Arquitect Abbott. Reducción de alcance 25.08.2015 de los siguientes ensayos: Ferritina, Reducción de alcance 14.01.2014 para los siguientes ensayos Digoxina, DL Colesterol Por fórmula Y Globulinas séricas Por fórmula
A18: Laboratorio de Hidrocarburos, Laboratorio Costarricense de Metrología | B18: Instituto Costarricense de Electricidad | C18: LE | D18: R | E18: Público | F18: LE-029 | G18: LE-026 | I18: ='17025 SAL'!$H18+$AN$1 -> 1460 | J18: 38635 | L18: Licda. Ileana Hidalgo | M18: ihidalgo@lacomet.go.cr | O18: 2224-3502 | P18: 2283-5133 | Q18: Costa Rica | R18: Ciudad de la investigación, San Pedro de Montes de Oca, Costa Rica. | AK18: Laboratorio Costarricense de Metrología
A19: Centro para Investigaciones en Granos y Semillas CIGRAS-UCR | B19: Universidad de Costa Rica | C19: LE | D19: A | E19: Académico | F19: LE-030 | G19: LE-028 | H19: 45147 | I19: ='17025 SAL'!$H19+$AN$1 -> 46607 | J19: 38635 | L19: Lic. Erika Villalobos Chaves | M19: erika.villalobos@ucr.ac.cr | N19: mariaveronica.campos@ucr.ac.cr | O19: 2511-8823 2511-3517 | P19: 2511-4346 | Q19: Costa Rica | R19: San José, Universidad de Costa Rica, Sede Rodrigo Facio, Contiguo a la Fac. de Ciencias Agroalimentarias, San Pedro de Montes de Oca. | S19: San José | T19: 4-000-042149 | U19: =HYPERLINK("http://www.cigras.ucr.ac.cr/;","http://www.cigras.ucr.ac.cr/;") -> http://www.cigras.ucr.ac.cr/; | V19: Carlos Araya Leandro | W19: 3-0305-0948 | X19: Casado | Y19: Costarricense | Z19: Doctor en Economía, Control y Gestión de Entidades y Políticas Públicas | AA19: San José, Universidad de Costa Rica, Sede Rodrigo Facio, Contiguo a la Fac. de Ciencias Agroalimentarias, San Pedro de Montes de Oca. | AB19: carlos.arayaleandro@ucr.ac.cr tel: 2511-1212 | AC19: Rector Universidad de Costa Rica | AD19: Jefatura Administrativa | AE19: M.B.A Armando Alvarado Luna | AF19: 2511 8822 | AG19: San José, Universidad de Costa Rica, Sede Rodrigo Facio, Contiguo a la Fac. de Ciencias Agroalimentarias, San Pedro de Montes de Oca. | AH19: NA | AI19: =HYPERLINK("mailto:armando.alvarado@ucr.ac.cr","armando.alvarado@ucr.ac.cr") -> armando.alvarado@ucr.ac.cr | AJ19: De lunes a viernes, de 8:00 a.m- 4:00 p.m. | AK19: UCR
A20: Laboratorio de Análisis Ambiental, Universidad Nacional | B20: Universidad Nacional | C20: LE | D20: A | E20: Académico | F20: LE-031 | G20: LE-024 | H20: 45681 | I20: No aplica | J20: 38635 | L20: José Felix Rojas Marin | M20: jose.rojas.marin@una.cr | N20: alejandra.gamboa@una.cr laa@una.ac.cr | O20: 2277-3292 EXT: 3508 | P20: 2277-3696 | Q20: Costa Rica | R20: Heredia, Edificio Rectoría de la UNA, Calle 9 Avenida central y primera.Laboratorio de Análisis Ambiental Tercer Piso, Escuela de Ciencias Ambientales, Campus Omar Dengo, UNA | S20: Heredia | T20: 4-000-042150-140 | U20: oe | V20: Jorge Herrera Murillo | W20: 205330454 | X20: Divorciado | Y20: Costarricense | Z20: Doctor en Ciencias de la Tierra con énfasis en Física de la Atmósfera | AA20: Heredia, Edificio Rectoría de la UNA, Calle 9 Avenida central y primera | AB20: rectoria@una.cr | AC20: Rector de la Universidad Nacional | AD20: Kerlyn Sánchez Campos | AE20: FUNDAUNA | AF20: 2263-7444 | AG20: Heredia, Edificio Rectoría de la UNA, Calle 9 Avenida central y primera | AH20: 2263-7444 | AI20: kerlin.sanchez.campos@una.cr; kersc_15@hotmail.com; | AJ20: De 8:00 a.m. hasta las 5:00 p.m | AK20: UNA | AL20: Suspensión parcial voluntario del 22/1/24 al 22/1/25
A21: Laboratorio de Ensayo Compañía Asesora de Construcción e Ingeniería S.A. CACISA | B21: Compañía Asesora de Construcción e Ingeniería CACISA Sociedad Anónima | C21: LE | D21: A | E21: Privado | F21: LE-032 | G21: LE-030 | H21: 45099 | I21: ='17025 SAL'!$H21+$AN$1 -> 46559 | J21: 38853 | L21: Ing. Elda Patricia Daniels Chang | M21: pdaniels@cacisa.cr | N21: rzuniga@cacisa.cr | O21: 2244-0548 | P21: 2244-1385 | Q21: Costa Rica | R21: Heredia, de la iglesia de Santa Rosa, 200 m oeste y 750 m norte, Sto. Domingo. | S21: Heredia | T21: 3-101-036290 | U21: =HYPERLINK("mailto:info@cacisa.cr","info@cacisa.cr") -> info@cacisa.cr | V21: Rodolfo De León rdeleon@cacisa.cr | W21: 900460935 | X21: Casado | Y21: Costarricense | Z21: Ingeniero Civil | AA21: Heredia, de la iglesia de Santa Rosa, 200 oeste y 750 norte, Sto. Domingo. | AC21: Director General | AD21: psalas@cacisa.cr | AE21: Paula Salas cuentas por pagar | AF21: 2244-0548 | AG21: Heredia, de la iglesia de Santa Rosa, 200 oeste y 750 norte, Sto. Domingo. | AH21: 2244-1385 | AI21: =HYPERLINK("mailto:cmontero@cacisa.cr","cmontero@cacisa.cr") -> cmontero@cacisa.cr | AJ21: L-V de 7:30 a.m. a 5:30 p.m. | AK21: CACISA
A22: Centro de Investigaciones en Nutrición Animal CINA-UCR | B22: Universidad de Costa Rica | C22: LE | D22: A | E22: Académico | F22: LE-033 | G22: LE-038 | H22: 45147 | I22: ='17025 SAL'!$H22+$AN$1 -> 46607 | J22: 39125 | K22: A03: 16/06/2025 | L22: Gerardo Soto Rodríguez | M22: calidad.cina@ucr.ac.cr | N22: calidad.cina@gmail.com | O22: 2511-2028 / 2511-2049 | P22: 2234-2415 | Q22: Costa Rica | R22: San José, 150 m oeste y 25 m sur de la UNED carretera a Sabanilla de Montes de Oca. | S22: San José | T22: 4-000-042149 | U22: =HYPERLINK("http://www.cina.ucr.ac.cr/","www.cina.ucr.ac.cr ") -> www.cina.ucr.ac.cr | V22: Carlos Araya Leandro | W22: 3-0305-0948 | X22: Casado | Y22: Costarricense | Z22: Doctor en Biología con especialidad en Genética | AA22: San José, Sede Univesitaria Rodrigo Facio, Edificio Administrativo B, Segundo Piso, Oficina de Rectoría, San Pedro de Montes de Oca | AC22: Rector Universidad de Costa Rica | AD22: Jenny Ascencio Ayala | AE22: Universidad de Costa Rica | AF22: 25113002 | AG22: San José, 150 oeste y 25 sur de la UNED carretera a Sabanilla de Montes de Oca. | AH22: 22342415 | AI22: =HYPERLINK("mailto:jenny.ascencio@ucr.ac.cr","jenny.ascencio@ucr.ac.cr ") -> jenny.ascencio@ucr.ac.cr | AJ22: L-V 8:00am a 4:30pm | AK22: UCR | AL22: La Gerencia de Calidad será asumida por el Bach. Fabio Granados Chinchilla, la Dra. Guadalupe Molina Chavarría será a su vez sustito de éste.
A23: Centro de Investigaciones Agronómicas CIA UCR | B23: Universidad de Costa Rica | C23: LE | D23: A | E23: Académico | F23: LE-036 | G23: LE-033 | H23: 45147 | I23: ='17025 SAL'!$H23+$AN$1 -> 46607 | J23: 38880 | L23: Marianela Blanco Morice | M23: sistemacalidad.cia@ucr.ac.cr marianela.blancomorice@ucr.ac.cr | N23: freddy.blanco@ucr.ac.cr gestoriatecnica.lsf@ucr.ac.cr | O23: 2511-2072 2511-3112 2511-2079 | P23: 2234-1627 | Q23: Costa Rica | R23: San José, Ciudad de la Investigación, Finca 2 UCR, de la UNED carretera a Sabanilla, 175 m este y 100 m sur, edificio de 3 pisos a mano izquierda, Montes de Oca. | S23: San José | T23: 3006101757 | U23: =HYPERLINK("http://www.cia.ucr.ac.cr/","www.cia.ucr.ac.cr ") -> www.cia.ucr.ac.cr | V23: Carlos Araya Leandro | W23: 3-0305-0948 | X23: Casado | Y23: Costarricense | Z23: Doctor en Biología con especialidad en Genética | AA23: San José, Sede Univesitaria Rodrigo Facio, Edificio Administrativo B, Segundo Piso, Oficina de Rectoría, San Pedro de Montes de Oca. | AC23: Rector Universidad de Costa Rica | AD23: María Gabirela Villegas Jefatura Administrativa CIA | AE23: FUNDEVI | AF23: 2511-2053 | AG23: San José, Ciudad de la Investigación, Finca 2 UCR, de la UNED carretera a Sabanilla, 175 este y 75 sur, Montes de Oca. | AH23: 2234-1627 | AI23: =HYPERLINK("mailto:maria.villegas@ucr.ac.cr","maria.villegas@ucr.ac.cr ") -> maria.villegas@ucr.ac.cr | AJ23: Lunes a Viernes de 8 a.m. a 5 p.m. | AK23: UCR | AL23: La factura debe venir a nombre de FUNDEVI pero debe entregarse en el CIA
A24: Consultora Costarricense para Programas de Desarrollo S.A COPRODESA | B24: Consultora Costarricense para Programas de Desarrollo S.A COPRODESA | C24: LC | D24: A | E24: Privado | F24: LC-038 | G24: LC-031 | H24: 45859 | I24: No aplica | J24: 38810 | L24: Jean Carlo Sandí Jiménez Sara Granados | M24: jsandi@coprodesa.com | N24: sgranados@coprodesa.com | O24: 2528-5880 | P24: 2283-1838 | Q24: Costa Rica | R24: San José, 75 m Sur de la Mitsubishi, Curridabat. | S24: San José | T24: 3-101-026507 | U24: =HYPERLINK("http://www.coprodesa.com/","www.coprodesa.com ") -> www.coprodesa.com | V24: Mario Longan Espinoza | W24: 1-0369-0348 | X24: Casado | Y24: Costarricense | Z24: Empresario | AA24: San José, 75 Sur de la Mitsubishi, Curridabat. | AC24: No tiene cargo en el Laboratorio sin embargo es parte de la Junta Directiva de la Empresa | AD24: Jennifer Mejía Castro | AE24: COPRODESA | AF24: 2528-5880 | AG24: San José, 75 Sur de la Mitsubishi, Curridabat. | AH24: 2283-1838 | AI24: =HYPERLINK("mailto:jmejia@coprodesa.com","jmejia@coprodesa.com") -> jmejia@coprodesa.com | AJ24: Todos los jueves de 9 a.m. a 5 p.m. (jornada continua) | AK24: Consultora Costarricense para Programas de Desarrollo S.A COPRODESA | AL24: 25/5/23: Con respecto a los representantes ante el ECA, se procede de la siguiente manera: Eliminar a Alonso Porras Cabezas como representante. Mantener a Jean Carlo Sandí Jiménez como representante. Agregar a Sara Granados Valverde como representante. De ahora en adelante por favor dirigirse a los siguientes correos para las notificaciones y avisos que nos deban dar: jsandi@coprodesa.com - Jean Carlo Sandí sgranados@coprodesa.com - Sara Granados
A25: Laboratorio de Ensayo del Centro de Electroquímica y Energía Química CELEQ | B25: Universidad de Costa Rica | C25: LE | D25: A | E25: Académico | F25: LE-040 | G25: LE-037 | H25: 45147 | I25: ='17025 SAL'!$H25+$AN$1 -> 46607 | J25: 39069 | K25: A07: 28/04/2025 | L25: Mariann Guillén Osorno | M25: calidad.celeq@ucr.ac.cr direccion.celeq@ucr.ac.cr | N25: jean.sanabria@ucr.ac.cr | O25: 2511-2487 | P25: 2511-2484 | Q25: Costa Rica | R25: San José, U.C.R Ciudad de la Investigación, San Pedro de Montes de Oca. | S25: San José | T25: 4-000-042149 | U25: =HYPERLINK("http://celeq.ucr.ac.cr/","http://celeq.ucr.ac.cr/ ") -> http://celeq.ucr.ac.cr/ | V25: Carlos Araya Leandro | W25: 3-0305-0948 | X25: Casado | Y25: Costarricense | Z25: Doctor en Biología con especialidad en Genética | AA25: San José, Sede Univesitaria Rodrigo Facio, Edificio Administrativo B, Segundo Piso, Oficina de Rectoría, San Pedro de Montes de Oca. | AC25: Rector Universidad de Costa Rica | AD25: Licda. Marjorie Badilla | AE25: Fundevi | AF25: 2511-3217 | AG25: San José, U.C.R Ciudad de la Investigación, San Pedro de Montes de Oca. | AH25: 2511-3211 | AI25: =HYPERLINK("mailto:mbadillad@hotmail.com","mbadillad@hotmail.com") -> mbadillad@hotmail.com | AJ25: 8 a.m. a 4 p.m. | AK25: UCR | AL25: La Factura debe venir a nombre de Fundevi, pero se debe recibir en el Celeq primero para enviar el trámite a Fundevi
A26: Laboratorio de Aseguramiento de la Calidad, Ingenio Taboga | B26: Laboratorio de Aseguramiento de la Calidad, Ingenio Taboga | C26: LE | D26: R | E26: Privado | F26: LE-041 | G26: LE-074 | H26: 44738 | I26: ='17025 SAL'!$H26+$AN$1 -> 46198 | J26: 40295 | L26: Martha Nuñez Torres | M26: mnunez@taboga.cr | N26: gdiaz@taboga.cr; jrodriguez@chemlabsonline.com | O26: 2674 0935 ext 1323 | P26: N/A | Q26: Costa Rica | R26: Guanacaste, Bebedero, Cañas. Para notificaciones: San José, Almacén Carazo en la Uruca | S26: Guanacaste | T26: 3-101-024153-03 | U26: NA | V26: Daniel Carvajal Carvajal | W26: 111120255 | X26: casado | Y26: costarricense | Z26: administrador de empresas. | AA26: San José, Almacén Carazo en La Uruca | AG26: San José, Almacén Carazo en La Uruca | AI26: NA | AK26: Taboga | AL26: Se le solicito en varias ocasiones la información faltante para completarla en el Directorio, sin obtener respuesta.
A27: Laboratorio Metrológico de Variables Eléctricas, LMVE-ICE | B27: Instituto Costarricense de Electricidad | C27: LC | D27: R | E27: Público | F27: LC-042 | G27: LC-036/125 | H27: 44348 | I27: ='17025 SAL'!$H27+$AN$1 -> 45808 | J27: 39034 | L27: Javier Robles Cordero, Blanca Castro Blanco,Lucrecia Montero Aguilar | M27: JRoblesCo@ice.go.cr | N27: BCastro@ice.go.cr; | O27: 2001-2374/75 | P27: NA | Q27: Costa Rica | R27: San José, Edificio ICE, Quinto Piso, Puerta # 11, San Pedro de Montes de Oca. | S27: San José | T27: =HYPERLINK("http://www.grupoice.com/","4-000-421-39 ") -> 4-000-421-39 | U27: =HYPERLINK("http://www.grupoice.com/","www.grupoice.com") -> www.grupoice.com | V27: Luis Pacheco Morgan | W27: 104620902 | X27: Casado | Y27: Costarricense | Z27: Ingeniero Químico | AA27: San José, 400 norte del edificio central del ICE, puesto de guarda a mano izquierda, edificio UEN PySA, piso 1, Sabana norte. | AC27: Gerente Sector Energía | AD27: Carmen Elena Rojas Zumbado | AE27: Laboratorio Metrológico de Variables Eléctricas, LMVE-ICE | AF27: 2000-5485 | AG27: San José, Edificio UEN PySA, 3° Piso, Centro de Servicio Investigación y Desarrollo, Sabana Norte. | AH27: 2220-8684 | AI27: JRoblesCo@ice.go.cr; BCastro@ice.go.cr; | AJ27: 7 am a 4:36 pm de L a V | AK27: ICE | AL27: 12.01.2016 reducción de alcance para las calibraciones de resistencia CD, medidores de resistencia CD, valores intermedios, Teraohmetros de 10 - 100 MW y de 1 - 100 GW
A28: Unidad de Laboratorio Metrológicos del Negocio Generación | B28: Instituto Costarricense de Electricidad | C28: LC | D28: A | E28: Público | F28: LC-042/138 | G28: LC-036/125 | H28: 44022 | I28: ='17025 SAL'!$H28+$AN$1 -> 45482 | J28: 39034 | K28: A01: 7-6-21 A02: 26-4-23 | L28: Javier Robles Cordero, Blanca Castro Blanco | M28: JRoblesCo@ice.go.cr | N28: BCastro@ice.go.cr | O28: 2000-4517 o 2001-2374 | P28: NA | Q28: Costa Rica | R28: Plantel ICE Colima, Tibás, San José. | S28: San José | T28: 4000042139 | U28: https://www.grupoice.com/wps/portal/ICE/electricidad/laboratorioss/lab | V28: José Joaquín Granados Ramírez | W28: 302970039 | X28: Soltero | Y28: Costarricense | Z28: Ingeniero Electromecánico | AA28: San José, Mata Redonda, Sabana Sur, Edificio ICE, Torre de Telecomunicaciones, Piso # 14 División Generación San José, Costa Rica | AB28: jogranados@ice.go.cr | AC28: Jefe División Generación | AD28: Cadena de Abastecimiento - División Generación | AE28: Sandra Hidalgo Cabrera | AF28: 2000-3087 | AG28: San José, Mata Redonda, Sabana Sur, Edificio ICE, Torre de Telecomunicaciones, Piso # 14 División Generación San José, Costa Rica | AH28: No aplica | AI28: shidalgo@ice.go.cr | AJ28: L a V de 7 am a 4:36 pm | AK28: ICE | AL28: 2020.08.19: Se acuerda unificar los laboratorio LACALI y LMVE y crear este OEC. // 12.01.2016 reducción de alcance para las calibraciones de resistencia CD, medidores de resistencia CD, valores intermedios, Teraohmetros de 10 - 100 MW y de 1 - 100 GW
A29: Laboratorio Punta Morales LAICA | B29: Liga Agricola Industrial de la caña de azucar | C29: LE | D29: A | E29: Público | F29: LE-043 | G29: LE-044 | H29: 45869 | I29: No aplica | J29: 39307 | L29: Reyner Alpízar Medina | M29: ralpizar@laica.co.cr | O29: 2661-0884 ext:129 | P29: 2661-0566 | Q29: Costa Rica | R29: Puntarenas, Punta Morales de Chomes. | S29: Puntarenas | T29: 3-007-42036 | U29: =HYPERLINK("http://www.laica.co.cr/","www.laica.co.cr") -> www.laica.co.cr | V29: Edgar Herrera Echadi | W29: 1-522-0490 | X29: Casado | Y29: costarricese | Z29: Administrador de negocios | AA29: San José, detrás del Ministerio de Trabajo, Barrio Tournon. | AC29: No tiene | AD29: Gabriela Sánchez | AE29: LAICA | AF29: 22846043 | AG29: San José, detrás del Ministerio de Trabajo, Barrio Tournon. | AH29: 26610566 | AI29: msanchez@laica.co.cr | AJ29: 09:00 a 10:30 | AK29: LAICA | AL29: No
A30: Laboratorio de Pruebas Físicas de Producto Terminado de Bridgestone de Costa Rica S.A. | B30: Bridgestone de Costa Rica Sociedad Anónima | C30: LE | D30: A | E30: Privado | F30: LE-044 | G30: LE-041 | H30: 45272 | I30: ='17025 SAL'!$H30+$AN$1 -> 46732 | J30: 39209 | L30: Carlos Alberto Martínez Sanchez/ Rixi Leiva | M30: martinezsanchezcarlos@la-bridgestone.com | N30: LeivaRixi@la-bridgestone.com | O30: 2209-7381/2209-7385 2209-7300 extensión 7083. | P30: 2209-7301 | Q30: Costa Rica | R30: Heredia, La Ribera, Kilometro 11, Autopista General Cañas, Belén. | S30: Heredia | T30: 3-101-008915 | U30: https://www.bridgestone.co.cr | V30: José Fernando Lopez Lopez. | W30: 122201367821 | Y30: Salvadoreño | AA30: Heredia, La Ribera, Kilometro 11, Autopista General Cañas, Belén. | AC30: Country Manager -Costa Rica Plant | AD30: Allan Soto Castrillo | AE30: Bridgestone de Costa Rica S.A | AF30: 22097300 | AG30: Heredia, La Ribera, Kilometro 11, Autopista General Cañas, Belén. | AH30: 22097301 | AI30: =HYPERLINK("mailto:alvarezronald@bfcr.co.cr","alvarezronald@bfcr.co.cr") -> alvarezronald@bfcr.co.cr | AJ30: de L a V de 8:00 am a 5 pm. | AK30: Laboratorio de Pruebas Físicas de Producto Terminado de Bridgestone de Costa Rica S.A.|
A31: Laboratorio del Centro Nacional de Ciencia y Tecnología de Alimentos CITA - UCR | B31: Universidad de Costa Rica | C31: LE | D31: A | E31: Académico | F31: LE-045 | G31: LE-035 | H31: 45147 | I31: ='17025 SAL'!$H31+$AN$1 -> 46607 | J31: 38971 | L31: Vanny Mora Villalobos | M31: vanny.mora@ucr.ac.cr | N31: marcy.gonzalez@ucr.ac.cr | O31: 25113270 | P31: N/A | Q31: Costa Rica | R31: San José, UCR, Detrás de la Facultad de Agronomía, San Pedro Montes de Oca | S31: San José | T31: 4-000-042149 | U31: =HYPERLINK("http://www.cita.ucr.ac.cr/","www.cita.ucr.ac.cr") -> www.cita.ucr.ac.cr | V31: Carlos Araya Leandro | W31: 3-0305-0948 | X31: Casado | Y31: Costarricense | Z31: Doctor en Biología con especialidad en Genética | AA31: San José, Sede Univesitaria Rodrigo Facio, Edificio Administrativo B, Segundo Piso, Oficina de Rectoría, San Pedro de Montes de Oca. | AC31: Rector Universidad de Costa Rica | AD31: FUNDEVI | AE31: Fundación de la Universidad de Costa Rica para la Investigación | AF31: 2511-1777 | AG31: San José, UCR, Detrás de la Facultad de Agronomía, San Pedro Montes de Oca | AH31: 2225-3876 | AI31: =HYPERLINK("mailto:fundevi@ucr.ac.cr","fundevi@ucr.ac.cr") -> fundevi@ucr.ac.cr | AJ31: 8am a 4pm | AK31: UCR | AL31: 26.07.2017 reducción ensayode química para productos lacteos - Grasa método SA-MQ-008 / Reducción de alcance 25.08.2015 para los ensayos de: Prueba triangular, prueba de comparación por pares, prueba de duo trío y prueba de tres alternativas de selección forzada.
A32: Laboratorio Costarricense de Metrología | B32: Instituto Costarricense de Electricidad | C32: LC | D32: R | E32: Público | F32: LC-047 | G32: LC-039 | I32: ='17025 SAL'!$H32+$AN$1 -> 1460 | J32: 39125 | M32: mnunez@taboga.co.cr | O32: 2283-6580 | P32: 2283-5133 | Q32: Costa Rica | R32: Ciudad de la Investigación, San Pedro de Montes de Oca, Costa Rica | AK32: LACOMET
A33: Laboratorio Nacional de Servicios Veterinarios LANASEVE | B33: Servicio Nacional de Salud Animal (SENASA) | C33: LE | D33: A-S | E33: Público | F33: LE-048 | G33: LE-040 | H33: 44096 | I33: ='17025 SAL'!$H33+$AN$1 -> 45556 | J33: 39209 | L33: Jeremy Barrantes Zamora | M33: jjbarrantesz@senasa.go.cr fchaverri@senasa.go.cr | N33: Para temas legales: german.rojas.h@senasa.go.cr, bernardita.rojas.c@senasa.go.cr | O33: 2587-1785 | P33: 2260-8300 ext 2345 | Q33: Costa Rica | R33: Lagunilla Heredia, 2 Km. Oeste y 500 metros Norte de Jardines del Recuerdo, en el Campus Universitario Benjamín Núñez, | S33: Heredia | T33: 3-007-475206 | U33: =HYPERLINK("http://www.senasa.go.cr/senasa/sitio/;","http://www.senasa.go.cr/senasa/sitio/;") -> http://www.senasa.go.cr/senasa/sitio/; | V33: Luis Alberto Matamoros Cortés | W33: 6-0289-0018 | X33: Casado | Y33: Costarricense | Z33: Médico Veterinario | AA33: Heredia, Cantón Central, Distrito Ulloa, Lagunilla, Campus Benjamín Núñez.2 km Oeste y 500 m Norte de Jardines del Recuerdo | AB33: luis.matamoros.c@senasa.go.cr | AC33: Director General del Servicio Nacional de Salud Animal (SENASA) | AD33: Dirección Administrativa Financiera del SENASA, Departamento de Recursos Materiales | AE33: Jose Luis Meneses Guevara | AF33: 22571600 o 22571613 | AG33: Heredia, 2 Km. Oeste y 500 Norte de Jardines del Recuerdo, en el Campus Universitario Benjamín Núñez, Lagunilla. | AH33: 22386169 o 22620226 | AI33: =HYPERLINK("mailto:eddy.obando.a@senasa.go.cr","eddy.obando.a@senasa.go.cr; bryan.moreira.r@senasa.go.cr") -> eddy.obando.a@senasa.go.cr; bryan.moreira.r@senasa.go.cr | AJ33: 7:30 a 15:30 | AK33: MAG - Senasa | AL33: Acuerdo Ministerial número N° 001-2023-MAG de fecha 11 de septiembre de 2023, publicado en el Diario Oficial La Gaceta número 178 del 28 de septiembre de 2023; se nombró al señor Luis Alberto Matamoros Cortés,
A34: Ingeniería Técnica de Proyectos ITP | B34: Ingeniería Técnica de Proyectos ITP Sociedad Anónima | C34: LE | D34: A | E34: Privado | F34: LE-050 | G34: LE-050 | H34: 45533 | I34: No aplica | J34: 39517 | K34: A16: 6/12/2024 | L34: Shirleny Salas Picado | M34: shirleny.salas@itp.cr | N34: oscar.martinez@itp.cr | O34: 2220-1400 ext: 2005/2009/2010 | P34: 2290-9295 | Q34: Costa Rica | R34: San José, Contiguo a Repretel, diagonal al AMPM, La Uruca. | S34: San José | T34: 3-101-362220 | U34: =HYPERLINK("http://www.itp.co.cr/","www.itp.co.cr") -> www.itp.co.cr | V34: Marcela Bonilla Verdesia | W34: 110740098 | X34: Casada | Y34: Costarricense | Z34: Administradora de Empresas | AA34: San José, Contiguo a Repretel, diagonal al AMPM, La Uruca. | AC34: Gerente General | AD34: Alejandra Acuña | AE34: Ingeniería Técnica de Proyectos ITP | AF34: 2220-1400 | AG34: San José, Contiguo a Repretel, diagonal al AMPM, La Uruca. | AH34: 2296-2382 | AI34: =HYPERLINK("mailto:aacuna@itp.co.cr","aacuna@itp.co.cr") -> aacuna@itp.co.cr | AJ34: Lunes a Viernes 8 am a 5 pm | AK34: ITP | AL34: * Ampliación 22709/2016 /11.08.2017 Reducción de alcance para el ensayo suelo - cemento para la determinación de suelo - cemento para el metodo ITP-IT-064 método de ensayo para la elaboración y curado de especímenes de laboratorio para los ensayos de comprensión y Flexión de muestras de suelo cemento / 15.12.2016 Reducción de alcance para los ensayos de la sede Panamá ver acta CA-2016-040 / 12.04.2016 reducción de alcance para el metodos de ensayo ITP-IT-52 Método Superpave para mezclado y compactación de mezcla asfáltica en caliente 12.08.2014 Reducción del método ITP-IT-11 densidad de parafina a 25°C en mezclas asfálaticas
A35: CHEMLABS | B35: CHEMLABS SOCIEDAD ANÓNIMA | C35: LE | D35: A | E35: Privado | F35: LE-051 | G35: LE-043 | H35: 45482 | I35: No aplica | J35: 39244 | L35: José Armando Rodríguez Solano | M35: jrodriguez@chemlabsonline.com | O35: 2234-6339 | P35: 2283-9869 | Q35: Costa Rica | R35: Cartago, #42 Residencial Monzerrat Concepción de la Unión. | S35: Cartago | T35: 3-101-492724 | U35: =HYPERLINK("http://www.chemlabsonline.com/","www.chemlabsonline.com") -> www.chemlabsonline.com | V35: Jose Armando Rodriguez Solano | W35: 1-06710412 | X35: Casado | Y35: Costarricense | Z35: Lic. Químico | AA35: San José, #192 Residencial Altamonte, Granadilla de Curridabat. | AC35: Jefe del Laboratorio | AD35: Blanca Ramirez | AE35: Blanca Ramirez | AF35: 22346339 | AG35: San José, #192 Residencial Altamonte, Granadilla de Curridabat. | AH35: 2283-9869 | AI35: =HYPERLINK("mailto:bramirez@chemlabsonline.com","bramirez@chemlabsonline.com") -> bramirez@chemlabsonline.com | AJ35: 8 am-5pm | AK35: Chem labs
A36: Laboratorio de Control de Calidad de Industria Farmacéutica S.A. de C.V. (calibración) | C36: LC | D36: R | E36: Privado | F36: LC-052 | G36: LC-047 | I36: ='17025 SAL'!$H36+$AN$1 -> 1460 | J36: 39426 | L36: Brenda Xiomara Miranda Bueso | M36: =HYPERLINK("mailto:brenda.miranda@infarma.hn","brenda.miranda@infarma.hn; administracion.calidad@infarma.hn") -> brenda.miranda@infarma.hn; administracion.calidad@infarma.hn | O36: (504) 2225-1272 | P36: (504) 2225-0271 | Q36: Honduras | R36: Col El Prado, atrás de Corporacion Flores TOYOTA | T36: 0401-1977-01951 | U36: =HYPERLINK("http://www.infarma.hn/","www.infarma.hn") -> www.infarma.hn | V36: Liliana Andonie | W36: 0801-1958-04265 | X36: Soltera | Y36: Hondureña | Z36: Lic. En Administración de empresas | AA36: Col El Prado, atrás de Corporacion Flores TOYOTA | AC36: Junta Directiva | AD36: Cinthia Vasquez | AE36: Iris Martínez | AF36: (504) 22251272 | AG36: Col El Prado, atrás de Corporacion Flores TOYOTA | AH36: (504) 22250271 | AI36: =HYPERLINK("mailto:iris.martinez@infarma.hn","iris.martinez@infarma.hn") -> iris.martinez@infarma.hn | AJ36: 08 h 00 a 15 h00 de Lunes a Viernes | AK36: Industria Farmacéutica S.A. de C.V. | AL36: Retiro de acreditación 09.12.2014
A37: Laboratorio de Control de Calidad de Industria Farmacéutica S.A. de C.V. (ensayos) | C37: LE | D37: R | E37: Privado | F37: LE-053 | G37: LE-051 | I37: ='17025 SAL'!$H37+$AN$1 -> 1460 | J37: 39574 | L37: Brenda Xiomara Miranda Bueso | M37: =HYPERLINK("mailto:brenda.miranda@infarma.hn","brenda.miranda@infarma.hn; administracion.calidad@infarma.hn") -> brenda.miranda@infarma.hn; administracion.calidad@infarma.hn | O37: (504) 2225-1272 | P37: (504)2225-0271 | Q37: Honduras | R37: Col El Prado, atrás de Corporacion Flores TOYOTA | T37: 0401-1977-01951 | U37: =HYPERLINK("http://www.infarma.hn/","www.infarma.hn") -> www.infarma.hn | V37: Liliana Andonie | W37: 0801-1958-04265 | X37: Soltera | Y37: Hondureña | Z37: Lic. En Administración de empresas | AA37: Col El Prado, atrás de Corporacion Flores TOYOTA | AC37: Junta Directiva | AD37: Cinthia Vasquez | AE37: Iris Martínez | AF37: (504) 22251272 | AG37: Col El Prado, atrás de Corporacion Flores TOYOTA | AH37: (504) 22250271 | AI37: =HYPERLINK("mailto:iris.martinez@infarma.hn","iris.martinez@infarma.hn") -> iris.martinez@infarma.hn | AJ37: 08 h 00 a 15 h00 de Lunes a Viernes | AK37: Industria Farmacéutica S.A. de C.V. | AL37: Retiro de acreditación 09.12.2014
A38: Metrología Consultores S.A. | B38: Metrología Consultores Sociedad Anónima | C38: LC | D38: A | E38: Privado | F38: LC-054 | G38: LC-046 | H38: 45128 | I38: ='17025 SAL'!$H38+$AN$1 -> 46588 | J38: 39344 | L38: Luis Miranda | M38: lmiranda@metrocal.co.cr | N38: gerentecalidad@metrocalcr.com administracion@metrocalcr.com | O38: 2280-1347 | P38: 2253-4687 | Q38: Costa Rica | R38: San José, de la Municipalidad 75 este, 175 m sur, frente al Minisuper Victoria, Guadalupe. | S38: San José | T38: 3-101-194426 | U38: =HYPERLINK("http://www.metrocal.co.cr/","www.metrocal.co.cr") -> www.metrocal.co.cr | V38: Marco V. Martínez Quesada | W38: 1-0629-0585 | X38: Casado | Y38: Costarricense | Z38: Físico y Meteorólogo | AA38: =HYPERLINK("mailto:mmartinez@metrocal.co.cr","Alajuela, 2 km este del Aeropuerto Internacional Juan Santamaría, Río Segundo de Alajuela .") -> Alajuela, 2 km este del Aeropuerto Internacional Juan Santamaría, Río Segundo de Alajuela . | AC38: Responsable Técnico | AD38: Sharon Chavarría Pérez | AE38: Sharon Chavarría Pérez | AF38: 2280-1347 | AG38: San José, de la Municipalidad 75 este, 175 sur, frente al Minisuper Victoria, Guadalupe. | AH38: 2253-4687 | AI38: =HYPERLINK("mailto:schavarria@metrocal.co.cr","schavarria@metrocal.co.cr") -> schavarria@metrocal.co.cr | AJ38: L-V 7:30 am a 5:00 pm | AK38: Metrología Consultores S.A. | AL38: N/A
A39: Laboratorio Nacional de Aguas AyA | B39: Instituto Costarricense de Acueductos y Alcantarillados | C39: LE | D39: A | E39: Público | F39: LE-055 | G39: LE-049 | H39: 44159 | I39: ='17025 SAL'!$H39+$AN$1 -> 45619 | J39: 39489 | K39: LE-049-A01 13 de julio del 2007. LE-049-A02 06 de diciembre del 2011. LE-049-A03 01 de julio del 2014. LE-049-A04 09 de febrero del 2016. LE-049-A05 10 de mayo del 2016. LE-049-A06 01 de diciembre del 2017. LE-049-A07 30 de octubre del 2018. LE-049-A08 22 de febrero del 2022. LE-049-A09 08 de abril del 2022. | L39: Ilena Vega Guzmán | M39: ivega@aya.go.cr | N39: nalfaro@aya.go.cr | O39: 2242-5000, ext. 6538 | P39: 2279-5973 | Q39: Costa Rica | R39: Cartago, 400 m norte del edificio municipal, La Unión de Tres Ríos. | S39: Cartago | T39: 4-000-042138 | U39: =HYPERLINK("http://www.aya.go.cr/","www.aya.go.cr") -> www.aya.go.cr | V39: José Alberto Moya Segura | W39: 1-0538-0956 | X39: Casado | Y39: Costarricense | Z39: Ingeniero Industrial | AA39: Cartago, 400 Norte de la Municipalidad de Tres Ríos, La Unión | AC39: Gerente General. | AD39: Lic. Marco Antonio Sequeira Barquero | AE39: Lic. Marco Antonio Sequeira Barquero | AF39: 22795118 | AG39: Cartago, 400 norte del edificio municipal, La Unión de Tres Ríos. | AH39: 22795973 | AI39: =HYPERLINK("mailto:msequeira@aya.go.cr","msequeira@aya.go.cr") -> msequeira@aya.go.cr | AJ39: 07:45 - 16:00 | AK39: A Y A
A40: OJM Consultores de Calidad y Laboratorios S.A. | B40: OJM Consultores de Calidad y Laboratorios Sociedad Anónima | C40: LE | D40: A | E40: Privado | F40: LE-056 | G40: LE-066 | H40: 44009 | I40: ='17025 SAL'!$H40+$AN$1 -> 45469 | J40: 40099 | K40: LE-066-A01: 26 de abril del 2011. LE-066-A02: 28 de octubre del 2014. LE-066-A03: 26 de enero del 2016. LE-066-A04: 26 de enero del 2016. LE-066-A05: 08 de diciembre del 2016. LE-066-A06: 29 de diciembre del 2016. LE-066-A07: 11 de mayo del 2017. LE-066-A08:27de Octubredel2017. LE-066-A09: 17 de junio 2021. LE-066-A10: 24 de agosto del 2021. | L40: José Luis Loría Álvarez Alfredo Salas Murillo | M40: calidad@ojmconsultores.com | N40: a.salas@ojmconsultores.com | O40: 2226-4078 / 83273421 | P40: No aplica | Q40: Costa Rica | R40: San Jose, Curridabat, Curridabat. Del Archivo Nacional, 50 metros este, junto a CRECEX de Costa Rica. | S40: San José | T40: 3-101-449145 | U40: N.A | V40: Alfredo Salas Murillo | W40: 1-1125-0222 | X40: Casado | Y40: Costarricense | Z40: sociólogo | AA40: San Jose, Curridabat, Curridabat. Del Archivo Nacional, 50 metros este, junto a CRECEX de Costa Rica. | AC40: Gerente General | AD40: No indica | AE40: Alfredo Salas Murillo | AF40: 2226-4078 / 8327-3421 | AG40: 50 metros al este y 25 metros al sur del Archivo Nacional, Curridabat, San José. | AH40: No aplica | AI40: facturacion@ojmconsultores.com | AJ40: 8:00 am a 5:00pm de Lunes a Viernes | AK40: OJM Consultores de Calidad y Laboratorios S.A. | AL40: 14/6/2019. Transición a la Norma INTE-ISO/IEC 17025:2017 y mantenimiento de acreditación
...

Sheet 17020 SAI
B1: Norma de Referencia: INTE ISO/IEC 17020:2012 Evaluación de la conformidad. Requisitos para el funcionamiento de diferentes tipos de organismos que realizan la inspección.
A2: Nombre del OEC | B2: Nombre Razón social | C2: Tipo OEC | D2: Estatus | E2: Sector | F2: # Expediente | G2: # Acreditación | H2: Fecha firma de contrato | I2: Renovación de contrato | J2: Fecha de Otorgamiento | K2: Resumen fecha ampliaciones | L2: Nombre Representante ante ECA | M2: Email para notificaciones (oficial) | N2: Email alternativos (copias de comunicación) | O2: Teléfono | P2: Fax | Q2: País | R2: Dirección | S2: Provincia | T2: Cédula Jurídica | U2: Sitio Web | V2: NombreRepresentante Legal | W2: # Identificación | X2: Estado Civil | Y2: Nacionalidad | Z2: Profesión | AA2: Dirección para recibir notificaciones | AB2: Correo electrónico | AC2: Cargo dentro del OEC: | AD2: Contacto Dpto. de Facturación/ Cobro | AE2: Nombre | AF2: Teléfono2 | AG2: Dirección3 | AH2: Fax4 | AI2: Email | AJ2: Horario de atención | AK2: Empresa | AL2: Observaciones
A3: Saybolt de Costa Rica S.A. | C3: OI | D3: R | E3: Privado | G3: OI-001 | I3: ='17020 SAI'!$H3+'17025 SAL'!$AN$1 -> 1460 | J3: 38054 | K3: N.A | M3: saybolt.cr.ops@corelab.com; eduardo.aguero@corelab.com | O3: 2290-4439 / 8880-7395 | P3: 2290-4680 | Q3: Costa Rica | R3: 50m Sur UCIMED, Sabana Oeste. San José (contiguo al Restaurante Órale) | AK3: Saybolt de Costa Rica S.A.
A4: Saybolt de Costa Rica S.A. | C4: OI | D4: N-P | E4: Privado | F4: OI-002 | I4: ='17020 SAI'!$H4+'17025 SAL'!$AN$1 -> 1460 | K4: N.A | L4: Eduardo Agüero | M4: eduardo.aguero@corelab.com; saybolt.cr.ops@corelab.com | O4: 2290-4439 / 8880-7395 | P4: 2290-4680 | Q4: Costa Rica | R4: 50m Sur UCIMED, Sabana Oeste. San José (contiguo al Restaurante Órale) | AK4: Saybolt de Costa Rica S.A.
A5: Intertek Testing Services Costa Rica, S.A | C5: OI | D5: R | E5: Privado | F5: OI-004 | G5: OI-002 | I5: ='17020 SAI'!$H5+'17025 SAL'!$AN$1 -> 1460 | J5: 38551 | K5: N.A | L5: Alexis Ayala Jurado | M5: alexis.ayala@intertek.com | O5: (507) 2329100 | P5: (507) 22325002 | Q5: Costa Rica | R5: Zona Procesadora de Exportacion Albrrok, Edificio No 6 | T5: 3-101-255234 | U5: www.intertek.com | V5: Alexis Ayala Jurado | W5: Pasaporte No 1768706 | X5: Casado | Y5: Panameño | Z5: Quimico | AA5: De la Estacion de Bomberos Barrio Lujan 100 Oeste, 15 Sur Edificio Jimenez Barletta, 3er Piso | AC5: Gerente General | AD5: Yamilette Camacho Cantillo | AE5: Intertek Testing Services Costa Rica S.A. | AF5: (506) 22564663 | AG5: De la Estacion de Bomberos Barrio Lujan 100 Oeste, 15 Sur Edificio Jimenez Barletta, 3er Piso | AH5: (506) 22564663 | AI5: yamilette.camacho@intertek.com | AJ5: Lunea a Viernes de 8:00 a 5:00 | AK5: Intertek Testing Services Costa Rica, S.A | AL5: Retiro de acreditación a partir del 08.04.2014, suspensión voluntaria total del alcance por 6 meses del 26.11.2013 al 13.08.2014
